File: data/Tensile/231016/engraved.txt
File Path: C:\Users\apk5101\Desktop\Sandra\23-10-13\Engraved_1 10-13-23 10 49 17 AM\DAQ- Crosshead, … - (Timed).txt
Test: MTS EM Tension (Simplified) with Video Extensometer apk5101 21
Test Run: Engraved_1
Date: 10/13/2023 10:13:34 AM


Crosshead 	Load 	Time 	Strain 1 	Video Time
mm	N	sec	mm/mm	sec
0.000833820422485587	0.0555258877575397	0.257999986410141	8.47994033392752E-06	15.6995000839233
0.00476468812848907	0.267151832580566	0.758000016212463	0.000119992000691127	16.2222995758057
0.00970805194810964	0.753361940383911	1.25800001621246	0.000646636995952576	16.7007999420166
0.0140558295242954	1.21673262119293	1.75800001621246	0.00120075000450015	17.1996002197266
0.0184036071004812	1.72256672382355	2.25799989700317	0.00154701003339142	17.699499130249
0.0224535924644442	2.24454855918884	2.75799989700317	0.00190277001820505	18.1996002197266
0.0268609292106703	2.90360140800476	3.25799989700317	0.00215601990930736	18.7996006011963
0.0309109127556439	3.51459050178528	3.75799989700317	0.00236721010878682	19.199499130249
0.0352586903318297	4.09453439712524	4.25799989700317	0.00254541006870568	19.6996002197266
0.0391895591747016	4.53392028808594	4.75799989700317	0.00275171990506351	20.1996002197266
0.0437160124420188	4.96319389343262	5.25799989700317	0.00282257003709674	20.6993999481201
0.0475873239338398	5.24542951583862	5.75799989700317	0.00285337003879249	21.1996002197266
0.051815983169945	5.45906591415405	6.25799989700317	0.00293009006418288	21.6996994018555
0.0556872910237871	5.64211225509644	6.75799989700317	0.00295895989984274	22.1993999481201
0.0602137442911044	5.82387924194336	7.25799989700317	0.00298832007683814	22.699499130249
0.0642041704850271	5.94827842712402	7.75799989700317	0.0030330999288708	23.199499130249
0.0685519480612129	6.0356707572937	8.25800037384033	0.00314143998548388	23.7994995117188
0.0726614962331951	6.12938213348389	8.75800037384033	0.00315622007474303	24.2994995117188
0.0770688275224529	6.18499803543091	9.25800037384033	0.00318679003976285	24.699499130249
0.0811188147054054	6.22668361663818	9.75800037384033	0.00317200995050371	25.1996994018555
0.0854070312925614	6.2858419418335	10.2580003738403	0.00319219008088112	25.6996002197266
0.0893974574864842	6.31494045257568	10.7580003738403	0.00321453996002674	26.199499130249
0.0936856813495979	6.34567546844482	11.2580003738403	0.0033514800015837	26.699499130249
0.0976165465544909	6.36963748931885	11.7580003738403	0.00336994999088347	27.199499130249
0.101964324130677	6.53104877471924	12.2580003738403	0.00337608996778727	27.6996002197266
0.105835635622498	6.53378772735596	12.7580003738403	0.00336321000941098	28.199800491333
0.110123852209654	6.65776634216309	13.2580003738403	0.00339184002950788	28.7992992401123
0.114233393105678	6.68193578720093	13.7580003738403	0.00339960004203022	29.2992992401123
0.118521616968792	6.75461912155151	14.2580003738403	0.00348372990265489	29.7141990661621
0.12286938726902	6.73346757888794	14.7580003738403	0.00351403001695871	30.1993007659912
0.126978935441002	6.71144151687622	15.2580003738403	0.00350817991420627	30.6991996765137
0.131207591039129	6.79634284973145	15.7580003738403	0.00352095998823643	31.1993999481201
0.135078909806907	6.72962093353271	16.257999420166	0.00350896990858018	31.6993999481201
0.139307565405034	6.77074432373047	16.757999420166	0.00351113989017904	32.1992988586426
0.143536235555075	6.73098134994507	17.257999420166	0.00360590009950101	32.6994018554688
0.148003120557405	6.77474689483643	17.757999420166	0.00361441005952656	33.2994003295898
0.151517087942921	6.55983114242554	18.257999420166	0.00357866007834673	33.7993011474609
0.15610309492331	6.69747018814087	18.757999420166	0.00360366003587842	34.1994018554688
0.160212643095292	6.68989324569702	19.257999420166	0.00360062997788191	34.7990989685059
0.164560420671478	6.7157826423645	19.757999420166	0.003580889897421	35.1991996765137
0.168550846865401	6.65022277832031	20.257999420166	0.00364260002970695	35.6991004943848
0.172898624441586	6.69885492324829	20.757999420166	0.00362088996917009	36.1991996765137
0.176829489646479	6.65531253814697	21.257999420166	0.00363990990445018	36.6991004943848
0.180939023266546	6.62744331359863	21.757999420166	0.00364330993033946	37.1991996765137
0.185108132427558	6.64148473739624	22.257999420166	0.00363301998004317	37.7025985717773
0.189575031981803	6.7226734161377	22.757999420166	0.00361603009514511	38.2990989685059
0.19368456560187	6.70039319992065	23.257999420166	0.00369034009054303	38.7990989685059
0.197734552784823	6.72581481933594	23.757999420166	0.00369089003652334	39.2990989685059
0.201784539967775	6.78566408157349	24.257999420166	0.00369696994312108	39.6991004943848
0.206013195565902	6.76325750350952	24.757999420166	0.00370190991088748	40.2122001647949
0.210182304726914	6.79310417175293	25.257999420166	0.00368601991795003	40.7042007446289
0.21447052131407	6.77423858642578	25.757999420166	0.00369208003394306	41.2120018005371
0.218460947507992	6.78112506866455	26.257999420166	0.00375025998800993	41.6991004943848
0.222391812712885	6.71220445632935	26.757999420166	0.00375387002713978	42.1991004943848
0.226739590289071	6.85226631164551	27.257999420166	0.00376312993466854	42.8031005859375
0.231027806876227	6.95429372787476	27.757999420166	0.0037687299773097	43.2990989685059
0.235137355048209	6.97423648834229	28.257999420166	0.0037487200461328	43.6990013122559
0.239425571635365	6.97524070739746	28.757999420166	0.00376321002840996	44.1990013122559
0.243296890403144	7.03388929367065	29.257999420166	0.0037576500326395	44.6991004943848
0.247823336394504	7.15291976928711	29.757999420166	0.00384408002719283	45.1991004943848
0.2519924310036	7.18678522109985	30.257999420166	0.00383510999381542	45.6988983154297
0.256280647590756	7.16792917251587	30.757999420166	0.00381858996115625	46.1990013122559
0.260330649325624	7.25748157501221	31.257999420166	0.00382407009601593	46.6988983154297
0.264499743934721	7.31409502029419	31.757999420166	0.00381205999292433	47.1988983154297
0.268668838543817	7.32553434371948	32.257999420166	0.00382522004656494	47.798999786377
0.272897508693859	7.42630100250244	32.757999420166	0.00390407000668347	48.298900604248
0.277126178843901	7.58004808425903	33.257999420166	0.0039084698073566	48.7988014221191
0.280878361081704	7.55898857116699	33.757999420166	0.00392332021147013	49.2988014221191
0.285107031231746	7.74265241622925	34.257999420166	0.00391277018934488	49.7033996582031
0.289454794256017	7.7900857925415	34.757999420166	0.003912010230124	50.1990013122559
0.293802586384118	7.88159799575806	35.257999420166	0.0039092400111258	50.6988983154297
0.29779301257804	7.83572483062744	35.757999420166	0.00397307984530926	51.1988983154297
0.301723863231018	7.94508123397827	36.257999420166	0.00397629011422396	51.6990013122559
0.305654742987826	7.96455144882202	36.757999420166	0.00396563997492194	52.1988983154297
0.310240749968216	8.14490413665771	37.257999420166	0.00397313991561532	52.6987991333008
0.314171629725024	8.1264591217041	37.757999420166	0.00397128984332085	53.2988014221191
0.318876758683473	8.23837089538574	38.257999420166	0.00399868004024029	53.7988014221191
0.322688487358391	8.17487621307373	38.757999420166	0.00395803991705179	54.298698425293
0.326976733049378	8.26273345947266	39.257999420166	0.00403018016368151	54.6987991333008
0.330967159243301	8.29669380187988	39.757999420166	0.00406097993254662	55.2223014831543
0.335434044245631	8.43570327758789	40.257999420166	0.00403661979362369	55.6987991333008
0.339484016876668	8.42672348022461	40.757999420166	0.00405048998072743	56.1986999511719
0.343653140589595	8.48919296264648	41.257999420166	0.00403132988139987	56.6987991333008
0.347524444805458	8.5410099029541	41.757999420166	0.00403543980792165	57.1986999511719
0.351931783370674	8.65864849090576	42.257999420166	0.00409399997442961	57.7985992431641
0.355922209564596	8.65777206420898	42.757999420166	0.00410170014947653	58.2985992431641
0.360448641004041	8.80997276306152	43.257999420166	0.00410994002595544	58.8053016662598
0.364379520760849	8.87573528289795	43.757999420166	0.00409241020679474	59.298698425293
0.368608190910891	8.92071342468262	44.257999420166	0.00411918014287949	59.7130012512207
0.372717739082873	9.01924133300781	44.757999420166	0.00410558003932238	60.1986999511719
0.377005955670029	9.08607006072998	45.257999420166	0.00416183983907104	60.6986999511719
0.380996381863952	9.03417682647705	45.757999420166	0.00415892014279962	61.2125015258789
0.385403720429167	9.07948970794678	46.257999420166	0.00416905013844371	61.698600769043
0.389513239497319	9.12045574188232	46.757999420166	0.00416377978399396	62.1986999511719
0.39374190964736	9.15210056304932	47.257999420166	0.00416465988382697	62.7985000610352
0.397613213863224	9.10948753356934	47.757999420166	0.00415939977392554	63.2985000610352
0.401663215598091	9.08497142791748	48.257999420166	0.00415899977087975	63.698600769043
0.405713188229129	9.14433002471924	48.757999420166	0.00417562993243337	64.1985015869141
0.410001404816285	9.15861988067627	49.257999420166	0.00418362999334931	64.698600769043
0.414051406551152	9.20064449310303	49.757999420166	0.00417665997520089	65.1986999511719
0.418458716012537	9.32257175445557	50.257999420166	0.00418923003599048	65.6986999511719
0.422508717747405	9.36160659790039	50.757999420166	0.00415064999833703	66.198600769043
0.426975602749735	9.41309070587158	51.257999420166	0.00418013008311391	66.6985015869141
0.431025604484603	9.44888591766357	51.757999420166	0.00421865005046129	67.1985015869141
0.435313821071759	9.48126697540283	52.257999420166	0.00424851011484861	67.7985000610352
0.43954246211797	9.61718845367432	52.757999420166	0.00424748985096812	68.2985000610352
0.443592463852838	9.60134220123291	53.257999420166	0.00425637979060411	68.6985015869141
0.44770201202482	9.73688793182373	53.757999420166	0.004224160220474	69.1985015869141
0.451811560196802	9.75235462188721	54.257999420166	0.00423229997977614	69.6985015869141
0.456040201243013	9.86030292510986	54.757999420166	0.00424969010055065	70.1984024047852
0.460149749414995	9.90253353118896	55.257999420166	0.00430419994518161	70.6986999511719
0.464557087980211	10.0795526504517	55.757999420166	0.00431512016803026	71.1985015869141
0.46836884575896	10.0244417190552	56.257999420166	0.00430546002462506	71.6984024047852
0.472776184324175	10.1389932632446	56.757999420166	0.00429394980892539	72.1983032226563
0.476885732496157	10.2078695297241	57.257999420166	0.00427707005292177	72.7984008789063
0.480995251564309	10.2747297286987	57.757999420166	0.00432243011891842	73.2983016967773
0.485104799736291	10.3231611251831	58.257999420166	0.00437658000737429	73.7983016967773
0.489452562760562	10.3980808258057	58.757999420166	0.00436350982636213	74.2984008789063
0.493740779347718	10.4857320785522	59.257999420166	0.00435950979590416	74.6983032226563
0.498088600579649	10.562554359436	59.757999420166	0.00437698978930712	75.1984024047852
0.502019422128797	10.5934543609619	60.257999420166	0.0043397699482739	75.6983032226563
0.506188545841724	10.6991834640503	60.757999420166	0.00433288002386689	76.1981964111328
0.510357669554651	10.7730560302734	61.257999420166	0.00433424022048712	76.6984024047852
0.514109851792455	10.7497186660767	61.757999420166	0.00441484991461039	77.1983032226563
0.518457614816725	10.8251304626465	62.257999420166	0.00439359014853835	77.7983016967773
0.522686284966767	10.9752922058105	62.757999420166	0.00441227992996573	78.2982025146484
0.526617164723575	10.9918584823608	63.257999420166	0.00441162986680865	78.7982025146484
0.531084020622075	11.1370372772217	63.757999420166	0.00442676013335586	79.1983032226563
0.535014900378883	11.1344814300537	64.2580032348633	0.00439254008233547	79.6983032226563
0.539541360922158	11.2830600738525	64.7580032348633	0.00441465014591813	80.1984024047852
0.543472240678966	11.252010345459	65.2580032348633	0.00450605014339089	80.7004013061523
0.547939154785126	11.3818035125732	65.7580032348633	0.00445883022621274	81.2033004760742
0.551750883460045	11.3994960784912	66.2580032348633	0.00446513993665576	81.6981964111328
0.556098646484315	11.4851951599121	66.7580032348633	0.00447865994647145	82.2123031616211
0.560089072678238	11.5083494186401	67.2580032348633	0.00443971017375588	82.7982025146484
0.564496440347284	11.567554473877	67.7580032348633	0.00445778016000986	83.3037033081055
0.568427261896431	11.5933589935303	68.2580032348633	0.00443645985797048	83.697998046875
0.572834629565477	11.6474523544312	68.7580032348633	0.00450005009770393	84.2981033325195
0.576944148633629	11.6846561431885	69.2580032348633	0.00451599014922976	84.6988983154297
0.581470609176904	11.7991619110107	69.7580032348633	0.00449481001123786	85.1980972290039
0.58498460566625	11.7071094512939	70.2580032348633	0.00448992010205984	85.6980972290039
0.589570612646639	11.849663734436	70.7580032348633	0.00448851985856891	86.197998046875
0.593620585277677	11.9203758239746	71.2580032348633	0.00449198018759489	86.6980972290039
0.597849255427718	11.9481439590454	71.7580032348633	0.00451742019504309	87.197998046875
0.601780076976866	11.9634428024292	72.2580032348633	0.00451841996982694	87.697998046875
0.605949200689793	12.0730600357056	72.7580032348633	0.00452330010011792	88.2979965209961
0.610177870839834	12.1827659606934	73.2580032348633	0.00452399021014571	88.6981964111328
0.614346994552761	12.255578994751	73.7580032348633	0.00453052017837763	89.1978988647461
0.618635211139917	12.3473787307739	74.2580032348633	0.00451321993023157	89.6980972290039
0.622863823082298	12.4424295425415	74.7580032348633	0.00454044993966818	90.197998046875
0.62709249323234	12.5003213882446	75.2580032348633	0.00468533998355269	90.7135009765625
0.631380709819496	12.5932693481445	75.7580032348633	0.00458212988451123	91.197998046875
0.635490287095308	12.6021900177002	76.2580032348633	0.0045383800752461	91.7035980224609
0.639540259726346	12.7157907485962	76.7580032348633	0.00456563010811806	92.2979965209961
0.643471139483154	12.7380199432373	77.2580032348633	0.00457968004047871	92.7978973388672
0.647580658551306	12.78307056427	77.7580032348633	0.00455876020714641	93.2978973388672
0.651868875138462	12.9340467453003	78.2580032348633	0.00456818006932735	93.697998046875
0.655918847769499	12.9824457168579	78.7580032348633	0.00456003984436393	94.197998046875
0.660326215438545	13.1124897003174	79.2580032348633	0.00465408992022276	94.6978988647461
0.664376188069582	13.1029653549194	79.7580032348633	0.00463332980871201	95.1980972290039
0.668723951093853	13.2285661697388	80.2580032348633	0.00463466998189688	95.6977996826172
0.67289307480678	13.1979570388794	80.7580032348633	0.00460425997152925	96.1978988647461
0.677002593874931	13.3097448348999	81.2580032348633	0.00463736010715365	96.6978988647461
0.681112171150744	13.3214311599731	81.7580032348633	0.00460436008870602	97.2991027832031
0.6854003877379	13.4247283935547	82.2580032348633	0.00458717998117208	97.7993011474609
0.689331267494708	13.4006567001343	82.7580032348633	0.0047241197898984	98.2977981567383
0.693798123393208	13.5366353988647	83.2580032348633	0.00467327982187271	98.7977981567383
0.697669456712902	13.5716791152954	83.7580032348633	0.00464444980025291	99.1977996826172
0.702017219737172	13.6496601104736	84.2580032348633	0.00465103983879089	99.6986999511719
0.70594809949398	13.6590995788574	84.7580032348633	0.00465336022898555	100.197799682617
0.710236316081136	13.7371597290039	85.2580032348633	0.00465231016278267	100.697898864746
0.714405439794064	13.8028860092163	85.7580032348633	0.00465185986831784	101.199699401855
0.71869365638122	13.7648677825928	86.2580032348633	0.00467078993096948	101.697700500488
0.722743629012257	13.8594799041748	86.7580032348633	0.00473442021757364	102.297897338867
0.726972299162298	13.8481903076172	87.2580032348633	0.00470941001549363	102.797798156738
0.731022271793336	13.8680181503296	87.7580032348633	0.00469921994954348	103.197799682617
0.735191395506263	13.8125133514404	88.2580032348633	0.00469462992623448	103.699798583984
0.739360461011529	13.8781795501709	88.7580032348633	0.0046926299110055	104.199600219727
0.743648677598685	13.9453372955322	89.2580032348633	0.0047026202082634	104.697700500488
0.747639103792608	13.9113521575928	89.7580032348633	0.00467832991853356	105.197799682617
0.751927320379764	13.9504928588867	90.2580032348633	0.00474205985665321	105.697799682617
0.756096444092691	13.982367515564	90.7580032348633	0.00473223021253943	106.197700500488
0.760205963160843	13.9374904632568	91.2580032348633	0.00472122011706233	106.697700500488
0.764255993999541	13.9071798324585	91.7580032348633	0.00470262998715043	107.197601318359
0.768484605941921	14.0233945846558	92.2580032348633	0.00468363985419273	107.799102783203
0.772594183217734	14.0026655197144	92.7580032348633	0.00469292001798749	108.297500610352
0.776941946242005	14.0092401504517	93.2580032348633	0.00470987986773252	108.79759979248
0.781230162829161	14.0128421783447	93.7580032348633	0.00478366017341614	109.29759979248
0.785399286542088	13.9798374176025	94.2580032348633	0.00478438986465335	109.698501586914
0.789627956692129	14.0391941070557	94.7580032348633	0.00474198022857308	110.197700500488
0.793499231804162	13.8889589309692	95.2580032348633	0.00474872021004558	110.697601318359
0.797668355517089	13.9226322174072	95.7580032348633	0.00471417978405952	111.198501586914
0.801658781711012	13.8433094024658	96.2580032348633	0.00471069989725947	111.697601318359
0.806185242254287	13.9253435134888	96.7580032348633	0.00470888009294868	112.197700500488
0.810235214885324	13.8387269973755	97.2580032348633	0.00478834006935358	112.797897338867
0.814404338598251	13.9059562683105	97.7580032348633	0.00479409983381629	113.297500610352
0.818513857666403	13.8146543502808	98.2580032348633	0.00476743979379535	113.697700500488
0.822742527816445	13.8292350769043	98.7580032348633	0.00475715985521674	114.297500610352
0.826971197966486	13.7707777023315	99.2580032348633	0.00472870981320739	114.698501586914
0.830961624160409	13.7529726028442	99.7580032348633	0.00472737988457084	115.19750213623
0.834892445709556	13.6692008972168	100.258003234863	0.00477650016546249	115.697402954102
0.839359359815717	13.7749729156494	100.758003234863	0.00477574998512864	116.19750213623
0.84334978600964	13.6812429428101	101.258003234863	0.00475770002231002	116.699401855469
0.8478167001158	13.6572589874268	101.758003234863	0.0046808198094368	117.198997497559
0.851985765621066	13.5622873306274	102.258003234863	0.00467407004907727	117.797500610352
0.856393133290112	13.5602588653564	102.758003234863	0.00466550979763269	118.297500610352
0.86032401304692	13.4934110641479	103.258003234863	0.00463845999911427	118.797302246094
0.864671776071191	13.4573440551758	103.758003234863	0.00468397000804543	119.197601318359
0.868483504746109	13.3764028549194	104.258003234863	0.00466396985575557	119.700798034668
0.873188662808388	13.4739179611206	104.758003234863	0.00463772006332874	120.202903747559
0.876464357133955	13.2239189147949	105.258003234863	0.00462694000452757	120.697402954102
0.88110996875912	13.3120718002319	105.758003234863	0.00460771983489394	121.197303771973
0.884862150996923	13.2792301177979	106.258003234863	0.00459831999614835	121.697303771973
0.889269460458308	13.292706489563	106.758003234863	0.00458003021776676	122.213203430176
0.893319433089346	13.2423553466797	107.258003234863	0.00463561015203595	122.797401428223
0.897667254321277	13.220383644104	107.758003234863	0.00461651990190148	123.297302246094
0.901776773389429	13.1916055679321	108.258003234863	0.00458210986107588	123.797203063965
0.906243687495589	13.1307764053345	108.758003234863	0.00456660985946655	124.299003601074
0.910293660126626	12.9857969284058	109.258003234863	0.00452107004821301	124.697196960449
0.914462783839554	12.9401187896729	109.758003234863	0.00438995007425547	125.197303771973
0.91863184934482	12.8837337493896	110.258003234863	0.00455392990261316	125.697196960449
0.922681821975857	12.8301467895508	110.758003234863	0.00451942021027207	126.197303771973
0.926850945688784	12.7736377716064	111.258003234863	0.00432717008516192	126.711601257324
0.930900918319821	12.6701669692993	111.758003234863	0.00448225997388363	127.19709777832
0.935010495595634	12.5902338027954	112.258003234863	0.00446153990924358	127.797996520996
0.939417805057019	12.516902923584	112.758003234863	0.00440412992611527	128.302597045898
0.943527382332832	12.458384513855	113.258003234863	0.00446560001000762	128.797103881836
0.947398657444865	12.2507038116455	113.758003234863	0.0044504702091217	129.297103881836
0.952044210862368	12.2978954315186	114.258003234863	0.00442407000809908	129.69709777832
0.956094241701066	12.1694364547729	114.758003234863	0.00440918002277613	130.19709777832
0.960382458288223	12.1400566101074	115.258003234863	0.00437746988609433	130.697204589844
0.964372884482145	11.9484767913818	115.758003234863	0.0044229100458324	131.19709777832
0.96878019394353	11.9864435195923	116.258003234863	0.0043800501152873	131.697204589844
0.972889771219343	11.8413324356079	116.758003234863	0.00435116002336144	132.197204589844
0.97705889493227	11.7560634613037	117.258003234863	0.0043263197876513	132.79719543457
0.981168355792761	11.625039100647	117.758003234863	0.00432264991104603	133.297103881836
0.985635328106582	11.6393737792969	118.258003234863	0.00428758980706334	133.796997070313
0.989625696092844	11.5494966506958	118.758003234863	0.00433789007365704	134.297103881836
0.993854366242886	11.4997968673706	119.258003234863	0.00429377984255552	134.69709777832
0.99760654848069	11.3706855773926	119.758003234863	0.00427861977368593	135.197006225586
1.0017161257565	11.3448781967163	120.258003234863	0.00428103981539607	135.697006225586
1.00564700551331	11.2172870635986	120.758003234863	0.00423914007842541	136.196899414063
1.01011386141181	11.1744146347046	121.258003234863	0.00421342998743057	136.697006225586
1.01428292691708	11.1484422683716	121.758003234863	0.00424042996019125	137.197006225586
1.01886899210513	11.1021289825439	122.258003234863	0.00424771010875702	137.797103881836
1.02285936009139	10.9203681945801	122.758003234863	0.00417964020743966	138.296997070313
1.02726672776043	10.7758741378784	123.258003234863	0.00413603987544775	138.697006225586
1.03101890999824	10.6171092987061	123.758003234863	0.00411048997193575	139.197006225586
1.03524758014828	10.5784597396851	124.258003234863	0.00405529979616404	139.697006225586
1.03905936703086	10.4822254180908	124.758003234863	0.00419919984415174	140.196899414063
1.04358582757413	10.5210733413696	125.258003234863	0.00411682995036244	140.69709777832
1.04751670733094	10.3866214752197	125.758003234863	0.00409153988584876	141.197006225586
1.05186447035521	10.3283319473267	126.258003234863	0.00406523980200291	141.697006225586
1.05585483834147	10.1846418380737	126.758003234863	0.00406447006389499	142.19709777832
1.06026220601052	10.2046842575073	127.258003234863	0.00401925016194582	142.796905517578
1.06437178328633	10.0182027816772	127.758003234863	0.00403835019096732	143.296905517578
1.0687195463106	9.93760681152344	128.257995605469	0.00404016999527812	143.697006225586
1.07282912358642	9.83647918701172	128.757995605469	0.00403734995052218	144.196899414063
1.07705779373646	9.83715534210205	129.257995605469	0.00401411019265652	144.696899414063
1.08098855707794	9.77118396759033	129.757995605469	0.00400590011849999	145.222900390625
1.08521722722799	9.75850391387939	130.257995605469	0.003977179992944	145.696792602539
1.0893268045038	9.72581005096436	130.757995605469	0.00394689990207553	146.196792602539
1.09355547465384	9.67062187194824	131.257995605469	0.00402125017717481	146.712295532227
1.09790323767811	9.69818210601807	131.757995605469	0.00402172980830073	147.196792602539
1.10201281495392	9.65547943115234	132.257995605469	0.00398255977779627	147.796798706055
1.10618188045919	9.73472690582275	132.757995605469	0.00399666000157595	148.296905517578
1.11035094596446	9.67971038818359	133.257995605469	0.00397955998778343	148.696701049805
1.11434143036604	9.67500114440918	133.757995605469	0.00397454015910625	149.196792602539
1.11839140299708	9.63078117370605	134.257995605469	0.00401380006223917	149.696792602539
1.12244137562811	9.6175708770752	134.757995605469	0.00398888997733593	150.196792602539
1.12637225538492	9.49400520324707	135.257995605469	0.00397534994408488	150.696701049805
1.1308987159282	9.58276653289795	135.757995605469	0.0039623798802495	151.196701049805
1.13512738607824	9.52056694030762	136.257995605469	0.00394582003355026	151.696701049805
1.13959424197674	9.48873329162598	136.757995605469	0.00395249016582966	152.196701049805
1.14364421460778	9.41079330444336	137.257995605469	0.00395713001489639	152.79670715332
1.14775379188359	9.37200355529785	137.757995605469	0.00394464004784822	153.29670715332
1.1518633691594	9.32052516937256	138.257995605469	0.00392075022682548	153.796600341797
1.1561515275389	9.28365421295166	138.757995605469	0.00391433015465736	154.196594238281
1.1600824072957	9.2350959777832	139.257995605469	0.00389303988777101	154.696594238281
1.16448977496475	9.17586135864258	139.757995605469	0.00393805978819728	155.196594238281
1.16853974759579	9.14863967895508	140.257995605469	0.00392254022881389	155.696701049805
1.17288751062006	9.1403169631958	140.757995605469	0.0039284098893404	156.196594238281
1.17681839037687	9.09615135192871	141.257995605469	0.00390504999086261	156.696701049805
1.18116615340114	9.13805389404297	141.757995605469	0.00390202994458377	157.196594238281
1.18503742851317	9.02126979827881	142.257995605469	0.00386005011387169	157.796493530273
1.18956388905644	9.08972072601318	142.757995605469	0.00391155015677214	158.296905517578
1.19325658306479	8.95817565917969	143.257995605469	0.00389923993498087	158.696594238281
1.1979021364823	9.02824306488037	143.757995605469	0.00389481009915471	159.196502685547
1.20177341159433	8.95277881622314	144.257995605469	0.00387815991416574	159.696502685547
1.20624038390815	9.0456714630127	144.757995605469	0.00388239999301732	160.196502685547
1.21017126366496	8.95597267150879	145.257995605469	0.00383440009318292	160.696502685547
1.21451902668923	8.99160003662109	145.757995605469	0.00393628003075719	161.196502685547
1.21862848754972	8.93995571136475	146.257995605469	0.00393602019175887	161.696304321289
1.22285715769976	8.93811511993408	146.757995605469	0.00391254015266895	162.196502685547
1.22672854922712	8.81602954864502	147.257995605469	0.00389685994014144	162.796401977539
1.23095721937716	8.78621482849121	147.757995605469	0.00388040998950601	163.298492431641
1.2350071920082	8.813551902771	148.257995605469	0.0038599600084126	163.796493530273
1.23905716463923	8.78040790557861	148.757995605469	0.00392962014302611	164.197204589844
1.24352402053773	8.81011962890625	149.257995605469	0.00391140999272466	164.796401977539
1.24793138820678	8.74403285980225	149.757995605469	0.00390607002191246	165.196395874023
1.25186226796359	8.70599460601807	150.257995605469	0.00387603999115527	165.696395874023
1.25626951921731	8.69038677215576	150.757995605469	0.00387799995951355	166.196395874023
1.26031960826367	8.68479347229004	151.257995605469	0.00382900005206466	166.696395874023
1.26454816199839	8.61174297332764	151.757995605469	0.0038926899433136	167.196304321289
1.2686577392742	8.58178806304932	152.257995605469	0.00389418005943298	167.796295166016
1.27288640942425	8.43999004364014	152.757995605469	0.00387606001459062	168.296295166016
1.27687689382583	8.35792064666748	153.257995605469	0.00383897009305656	168.796295166016
1.28098635468632	8.262038230896	153.757995605469	0.00382130010984838	169.296295166016
1.28485774621367	8.14146041870117	154.257995605469	0.00378470006398857	169.696304321289
1.2892649974674	8.10567665100098	154.757995605469	0.00386088993400335	170.196395874023
1.29343417938799	8.06167793273926	155.257995605469	0.00384413008578122	170.696304321289
1.29766284953803	7.98127174377441	155.757995605469	0.00380899989977479	171.196304321289
1.30183191504329	7.86938619613647	156.257995605469	0.00379733997397125	171.696304321289
1.30600098054856	7.83573341369629	156.757995605469	0.00376605009660125	172.196197509766
1.3102296506986	7.83942079544067	157.257995605469	0.00373850995674729	172.796203613281
1.31457741372287	7.80958271026611	157.757995605469	0.00382187007926404	173.296295166016
1.31868699099869	7.7244930267334	158.257995605469	0.00378457992337644	173.796295166016
1.32261787075549	7.65821170806885	158.757995605469	0.00375385000370443	174.196197509766
1.32708472665399	7.70972013473511	159.257995605469	0.00375263998284936	174.696304321289
1.3308369088918	7.60799741744995	159.757995605469	0.00373707991093397	175.196105957031
1.33530388120562	7.67360925674438	160.257995605469	0.00370148988440633	175.696105957031
1.33953255135566	7.65133666992188	160.757995605469	0.00376329990103841	176.196197509766
1.34417810477316	7.69393587112427	161.257995605469	0.0037632801104337	176.696105957031
1.34810898452997	7.61923837661743	161.757995605469	0.00375481997616589	177.196105957031
1.35227805003524	7.73672866821289	162.257995605469	0.00372016010805964	177.796096801758
1.35585153475404	7.64080905914307	162.757995605469	0.00371361011639237	178.296203613281
1.36008020490408	7.64579916000366	163.257995605469	0.00369254010729492	178.796096801758
1.36413017753512	7.64105844497681	163.757995605469	0.00373389991000295	179.296005249023
1.36841845232993	7.60815763473511	164.257995605469	0.00373976002447307	179.796005249023
1.37264712247998	7.47711229324341	164.757995605469	0.00370773999020457	180.196197509766
1.37711397837847	7.47968864440918	165.257995605469	0.00368139008060098	180.695999145508
1.38110434636474	7.43263244628906	165.757995605469	0.00364760006777942	181.196105957031
1.38551171403378	7.38627290725708	166.257995605469	0.00363882002420723	181.696105957031
1.38944259379059	7.35361814498901	166.757995605469	0.00370271992869675	182.195999145508
1.39373086858541	7.30815315246582	167.257995605469	0.00370061001740396	182.695999145508
1.39795953873545	7.36224317550659	167.757995605469	0.00367828994058073	183.296005249023
1.4015925116837	7.27130126953125	168.257995605469	0.00367687991820276	183.796005249023
1.40588078647852	7.30758810043335	168.757995605469	0.00363949011079967	184.296005249023
1.41010945662856	7.29842567443848	169.257995605469	0.00359542993828654	184.7958984375
1.41409982461482	7.25421857833862	169.757995605469	0.00369147001765668	185.195907592773
1.41850719228387	7.22371053695679	170.257995605469	0.00367697002366185	185.695999145508
1.42249767668545	7.17355537414551	170.757995605469	0.00364039000123739	186.195907592773
1.42702413722873	7.15219640731812	171.257995605469	0.00362704996950924	186.695907592773
1.43101450521499	7.0912914276123	171.757995605469	0.00359138008207083	187.195907592773
1.43524317536503	7.11106014251709	172.257995605469	0.00356795010156929	187.695907592773
1.43947184551507	7.0942325592041	172.757995605469	0.00362943997606635	188.2958984375
1.44370051566511	7.109375	173.257995605469	0.00361642008647323	188.7958984375
1.44798867404461	7.10531759262085	173.757995605469	0.00360972993075848	189.2958984375
1.45191955380142	7.02420043945313	174.257995605469	0.00358105008490384	189.69580078125
1.45608861930668	7.01911401748657	174.757995605469	0.00357218994759023	190.19580078125
1.46031728945673	6.96695566177368	175.257995605469	0.0035409398842603	190.69580078125
1.46442686673254	6.86089706420898	175.757995605469	0.00356546998955309	191.19580078125
1.46871514152735	6.81555795669556	176.257995605469	0.00356730003841221	191.69580078125
1.47300329990685	6.8333306312561	176.757995605469	0.00354025000706315	192.19580078125
1.47681508678943	6.75899124145508	177.257995605469	0.00353141990490258	192.695693969727
1.48086505942047	6.84183979034424	177.757995605469	0.00350147997960448	193.295806884766
1.4849150320515	6.79899930953979	178.257995605469	0.00348809990100563	193.795806884766
1.48920330684632	6.80317783355713	178.757995605469	0.00356287998147309	194.295806884766
1.49361055810004	6.81977272033691	179.257995605469	0.00354965007863939	194.798400878906
1.49777974002063	6.87311840057373	179.757995605469	0.00356034003198147	195.19580078125
1.50177010800689	6.88765573501587	180.257995605469	0.00355205009691417	195.695693969727
1.50623696390539	6.97708082199097	180.757995605469	0.00351501000113785	196.195693969727
1.51022744830698	6.94742202758789	181.257995605469	0.00351193989627063	196.695693969727
1.51475390885025	7.04477882385254	181.757995605469	0.00359285995364189	197.195693969727
1.51850609108806	6.93218660354614	182.257995605469	0.0035555399954319	197.795700073242
1.52279436588287	6.90289258956909	182.757995605469	0.00353270000778139	198.295593261719
1.52666564099491	6.87502956390381	183.257995605469	0.00353860994800925	198.695693969727
1.53083470650017	6.82697868347168	183.757995605469	0.00348328007385135	199.195693969727
1.53506337665021	6.82047271728516	184.257995605469	0.00346722011454403	199.695602416992
1.53947074431926	6.75160217285156	184.757995605469	0.00356084993109107	200.195693969727
1.54340162407607	6.70519495010376	185.257995605469	0.00353152002207935	200.697006225586
1.54780887532979	6.69156837463379	185.757995605469	0.00351431011222303	201.195602416992
1.55197805725038	6.66523599624634	186.257995605469	0.00348686007782817	201.695602416992
1.55608751811087	6.64768838882446	186.757995605469	0.00345555995590985	202.195602416992
1.56037579290569	6.72938251495361	187.257995605469	0.00344659993425012	202.795501708984
1.56454485841095	6.7167820930481	187.757995605469	0.0035271099768579	203.295501708984
1.56847573816776	6.76123571395874	188.257995605469	0.00351621001027524	203.695602416992
1.57282350119203	6.82669973373413	188.757995605469	0.00352729996666312	204.195602416992
1.57669489271939	6.76205539703369	189.257995605469	0.00348896998912096	204.695602416992
1.58098305109888	6.76207399368286	189.757995605469	0.00349326990544796	205.198104858398
1.58503302372992	6.7996654510498	190.257995605469	0.00350127997808158	205.695495605469
1.58938078675419	6.89935159683228	190.757995605469	0.00354899000376463	206.195404052734
1.59349036403	6.89838552474976	191.257995605469	0.00354826007969677	206.695495605469
1.5979572199285	6.99862432479858	191.757995605469	0.00353536009788513	207.195404052734
1.60147121641785	6.91211748123169	192.257995605469	0.00352384010329843	207.695495605469
1.60617637448013	6.98850965499878	192.757995605469	0.00350974989123642	208.295593261719
1.61016674246639	7.01853466033936	193.257995605469	0.00347338011488318	208.795394897461
1.61445501726121	7.08307027816772	193.757995605469	0.00357052008621395	209.195495605469
1.61862408276647	7.1256103515625	194.257995605469	0.00357021996751428	209.695404052734
1.62267405539751	7.05565404891968	194.757995605469	0.00355202006176114	210.195495605469
1.62702181842178	7.13900899887085	195.257995605469	0.00354989990592003	210.695404052734
1.63107179105282	7.0689811706543	195.757995605469	0.00351459998637438	211.195999145508
1.63553876336664	7.15543079376221	196.257995605469	0.00350477988831699	211.695404052734
1.6395291313529	7.12342023849487	196.757995605469	0.00354637997224927	212.195297241211
1.64363870862871	7.14436960220337	197.257995605469	0.00355213996954262	212.695404052734
1.6476291930303	7.08071279525757	197.757995605469	0.00354347005486488	213.195297241211
1.65197695605457	7.15540409088135	198.257995605469	0.00352339004166424	213.695297241211
1.65596732404083	7.12500143051147	198.757995605469	0.00353530002757907	214.195297241211
1.6603150870651	7.16618013381958	199.257995605469	0.00349821010604501	214.795303344727
1.66430557146668	7.04893493652344	199.757995605469	0.00356669002212584	215.295303344727
1.66883203200996	7.05383968353271	200.257995605469	0.00353524996899068	215.695297241211
1.67240551672876	6.88522624969482	200.757995605469	0.003525469917804	216.195297241211
1.67711067479104	6.86991739273071	201.257995605469	0.00351420999504626	216.695297241211
1.68086285702884	6.7728271484375	201.757995605469	0.00348221999593079	217.195297241211
1.68527022469789	6.72591114044189	202.257995605469	0.00346512999385595	217.695205688477
1.68920098803937	6.57507705688477	202.757995605469	0.00351513992063701	218.195297241211
1.69372744858265	6.53086090087891	203.257995605469	0.00349071994423866	218.696502685547
1.69771793298423	6.43031454086304	203.757995605469	0.00347396009601653	219.195205688477
1.70218478888273	6.39597463607788	204.257995605469	0.0034808199852705	219.79719543457
1.70605618041009	6.31968784332275	204.757995605469	0.00343257002532482	220.295196533203
1.71046343166381	6.27163457870483	205.257995605469	0.00338476989418268	220.795104980469
1.71427521854639	6.21301412582397	205.757995605469	0.00346624990925193	221.195098876953
1.71856337692589	6.18928003311157	206.257995605469	0.00344391004182398	221.695205688477
1.72243476845324	5.93287563323975	206.757995605469	0.0033846499864012	222.195098876953
1.72690162435174	5.92752408981323	207.257995605469	0.00339113990776241	222.695098876953
1.73077289946377	5.73987293243408	207.757995605469	0.00335074006579816	223.195098876953
1.73553766217083	5.58661508560181	208.257995605469	0.00339036993682384	223.695098876953
1.73964712303132	5.4545578956604	208.757995605469	0.00335674011148512	224.195007324219
1.74375670030713	5.33250188827515	209.257995605469	0.00336900004185736	224.794998168945
1.74768758006394	5.21191644668579	209.757995605469	0.00333293993026018	225.295104980469
1.75215443596244	5.11159992218018	210.257995605469	0.0032493700273335	225.794998168945
1.75614492036402	5.00191593170166	210.757995605469	0.00325971003621817	226.295104980469
1.76049268338829	4.86990356445313	211.257995605469	0.00333125004544854	226.794998168945
1.76436395850033	4.79476928710938	211.757995605469	0.00330018997192383	227.194900512695
1.76877132616937	4.65218019485474	212.257995605469	0.00329144997522235	227.694900512695
1.7726426012814	4.60435152053833	212.757995605469	0.00325006991624832	228.194900512695
1.77669257391244	4.48489570617676	213.257995605469	0.00324604008346796	228.695007324219
1.78080215118825	4.38453245162964	213.757995605469	0.00320402998477221	229.194900512695
1.78514991421252	4.26559591293335	214.257995605469	0.00317351007834077	229.695007324219
1.78925949148834	4.26166820526123	214.757995605469	0.00325330998748541	230.294906616211
1.7934285569936	4.20115089416504	215.257995605469	0.00323531008325517	230.794906616211
1.79765722714365	4.15090227127075	215.757995605469	0.00325359008274972	231.294906616211
1.80194550193846	4.08365535736084	216.257995605469	0.00319460011087358	231.694900512695
1.8061741720885	4.00292348861694	216.757995605469	0.00318042002618313	232.194900512695
1.81022414471954	3.92143607139587	217.257995605469	0.00324546010233462	232.694900512695
1.81439321022481	3.83099031448364	217.757995605469	0.00322501990012825	233.194793701172
1.81856227573007	3.71643733978271	218.257995605469	0.00321280001662672	233.694900512695
1.82302924804389	3.65905022621155	218.757995605469	0.00318958004936576	234.195205688477
1.82690052315593	3.53928303718567	219.257995605469	0.00315858004614711	234.794799804688
1.83112919330597	3.53075933456421	219.757995605469	0.00314554991200566	235.294799804688
1.83494098018855	3.48740649223328	220.257995605469	0.00317717995494604	235.795196533203
1.83916965033859	3.45034742355347	220.757995605469	0.00318722007796168	236.19580078125
1.84339820407331	3.4375057220459	221.257995605469	0.00318003003485501	236.794799804688
1.84810336213559	3.42625761032104	221.757995605469	0.00312835001386702	237.194793701172
1.85227254405618	3.35888981819153	222.257995605469	0.003149010008201	237.694702148438
1.8565010977909	3.28420758247375	222.757995605469	0.00312196998856962	238.194793701172
1.86007469892502	3.24873352050781	223.257995605469	0.0031885199714452	238.694793701172
1.86436285730451	3.2649827003479	223.757995605469	0.00317471008747816	239.194702148438
1.8683533417061	3.21492552757263	224.257995605469	0.00318360002711415	239.694793701172
1.87264150008559	3.12106609344482	224.757995605469	0.0031475299037993	240.294692993164
1.87698926310986	3.11818695068359	225.257995605469	0.00314055010676384	240.794692993164
1.88109884038568	3.03900599479675	225.757995605469	0.00308498996309936	241.194595336914
1.88502972014248	2.99912977218628	226.257995605469	0.00315279001370072	241.694702148438
1.8893179949373	3.00417995452881	226.757995605469	0.00316883996129036	242.194702148438
1.89330836292356	2.98087954521179	227.257995605469	0.00316417007707059	242.694702148438
1.89771573059261	2.94504189491272	227.757995605469	0.00312553998082876	243.194595336914
1.90170609857887	2.90303063392639	228.257995605469	0.00308615993708372	243.694702148438
1.90599437337369	2.89107036590576	228.757995605469	0.00310358009301126	244.194702148438
1.9099252531305	2.80752944946289	229.257995605469	0.00317497993819416	244.694595336914
1.91463029477745	2.76915168762207	229.757995605469	0.003165960079059	245.29460144043
1.91844208166003	2.69601559638977	230.257995605469	0.00314566004090011	245.79460144043
1.92273035645485	2.64091420173645	230.757995605469	0.00310948002152145	246.29460144043
1.92689942196012	2.5764582157135	231.257995605469	0.00310115003958344	246.69450378418
1.93106848746538	2.43241095542908	231.757995605469	0.00309085007756948	247.194595336914
1.93517806474119	2.44730710983276	232.257995605469	0.00315450993366539	247.694595336914
1.93952582776546	2.34598159790039	232.757995605469	0.00311111006885767	248.194595336914
1.94375449791551	2.39012765884399	233.257995605469	0.00310289999470115	248.69450378418
1.94780447054654	2.32232642173767	233.757995605469	0.00306436000391841	249.19450378418
1.95203314069659	2.32724142074585	234.257995605469	0.00307583995163441	249.794494628906
1.95608311332762	2.28846120834351	234.757995605469	0.0030778800137341	250.294692993164
1.96066917851567	2.26645469665527	235.257995605469	0.00312874000519514	250.69450378418
1.9641830585897	2.21317672729492	235.757995605469	0.00312144006602466	251.194396972656
1.96859054267406	2.16704773902893	236.257995605469	0.00310654006898403	251.694396972656
1.972580794245	2.20462441444397	236.757995605469	0.00310181989334524	252.19450378418
1.9769286736846	2.19791793823242	237.257995605469	0.00304542994126678	252.694396972656
1.98097852990031	2.18844485282898	237.757995605469	0.00306565989740193	253.194396972656
1.98526680469513	2.15362811088562	238.257995605469	0.00313996011391282	253.69450378418
1.98925728909671	2.18696665763855	238.757995605469	0.00312758004292846	254.294403076172
1.99366454035044	2.20145416259766	239.257995605469	0.00312193995341659	254.794403076172
1.99789321050048	2.14763259887695	239.757995605469	0.00308327004313469	255.294296264648
2.00230069458485	2.14542675018311	240.257995605469	0.003089290112257	255.794296264648
2.0061123650521	2.0950653553009	240.757995605469	0.0030602898914367	256.294311523438
2.01010284945369	2.10966801643372	241.257995605469	0.00312545010820031	256.694396972656
2.01421231031418	2.00706124305725	241.757995605469	0.00314050004817545	257.194396972656
2.01844098046422	2.02555251121521	242.257995605469	0.00310291000641882	257.694396972656
2.02249106951058	1.97798454761505	242.757995605469	0.00308376993052661	258.194305419922
2.02701753005385	1.99129939079285	243.257995605469	0.00307113002054393	258.694213867188
2.03112699091434	1.94372773170471	243.757995605469	0.00305974995717406	259.194305419922
2.03487905673683	1.90375888347626	244.257995605469	0.00311136990785599	259.794311523438
2.03946512192488	1.92061269283295	244.757995605469	0.00311887008138001	260.294311523438
2.04369379207492	1.86368560791016	245.257995605469	0.00310475006699562	260.794311523438
2.04774388112128	1.86244463920593	245.757995605469	0.00307557010091841	261.194305419922
2.05227034166455	1.86777281761169	246.257995605469	0.0030722098890692	261.694213867188
2.05584382638335	1.86905419826508	246.757995605469	0.00306266010738909	262.194305419922
2.06031068228185	1.82607984542847	247.257995605469	0.00315289990976453	262.694213867188
2.06424156203866	1.8204038143158	247.757995605469	0.0031477699521929	263.194213867188
2.06870841793716	1.78315484523773	248.257995605469	0.0031246799044311	263.694213867188
2.07275850698352	1.78715622425079	248.757995605469	0.00308891991153359	264.194091796875
2.07686796784401	1.77012050151825	249.257995605469	0.00309079000726342	264.794097900391
2.08079884760082	1.78255677223206	249.757995605469	0.00307669001631439	265.294189453125
2.08508712239563	1.77233731746674	250.257995605469	0.00312784011475742	265.794097900391
2.08937516435981	1.82260799407959	250.757995605469	0.0031394399702549	266.294097900391
2.09378264844418	1.79360449314117	251.257995605469	0.00313041009940207	266.794403076172
2.09789210930467	1.8039653301239	251.757995605469	0.00310897990129888	267.194091796875
2.10212077945471	1.74419558048248	252.257995605469	0.00309422006830573	267.694091796875
2.10611126385629	1.70831799507141	252.757995605469	0.00306900008581579	268.194091796875
2.11022072471678	1.72180771827698	253.257995605469	0.00315383006818593	268.694091796875
2.11438979022205	1.71131503582001	253.757995605469	0.00312979007139802	269.194000244141
2.11855908855796	1.72797644138336	254.257995605469	0.00313754007220268	269.794006347656
2.122787758708	1.73253214359283	254.757995605469	0.00310952006839216	270.294006347656
2.12683761492372	1.75302910804749	255.257995605469	0.00309084006585181	270.794006347656
2.13100668042898	1.69595396518707	255.757995605469	0.00307955988682806	271.194000244141
2.13511637412012	1.68742120265961	256.257995605469	0.00316904997453094	271.694000244141
2.13946402072906	1.66151201725006	256.757995605469	0.00314606004394591	272.194000244141
2.14369269087911	1.61411571502686	257.257995605469	0.00314478995278478	272.694000244141
2.14792136102915	1.62434101104736	257.757995605469	0.00310323992744088	273.194000244141
2.15203082188964	1.64974522590637	258.257995605469	0.00310934009030461	273.693908691406
2.15625949203968	1.7080534696579	258.757995605469	0.00310020009055734	274.194000244141
2.16024997644126	1.66370832920074	259.257995605469	0.0031649200245738	274.693908691406
2.16447864659131	1.70186710357666	259.757995605469	0.00315500004217029	275.293914794922
2.16834992170334	1.65508198738098	260.257995605469	0.00314583000726998	275.797210693359
2.17281677760184	1.70557010173798	260.757995605469	0.00313016003929079	276.293914794922
2.1768668666482	1.63906276226044	261.257995605469	0.00309956003911793	276.793914794922
2.18121474608779	1.65091121196747	261.757995605469	0.00310005992650986	277.193908691406
2.1852646023035	1.54014599323273	262.257995605469	0.00316588999703526	277.693908691406
2.189374063164	1.52064776420593	262.757995605469	0.00314461998641491	278.193908691406
2.1931859664619	1.52831721305847	263.257995605469	0.00312769995070994	278.693908691406
2.1976528223604	1.51887261867523	263.757995605469	0.00312081002630293	279.193908691406
2.20176228322089	1.48437511920929	264.257995605469	0.00309866992756724	279.694213867188
2.20616976730525	1.47556793689728	264.757995605469	0.00308897998183966	280.293792724609
2.21016001887619	1.48031175136566	265.257995605469	0.00315926992334425	280.793792724609
2.21438868902624	1.43004894256592	265.757995605469	0.0031670699827373	281.293792724609
2.2166520357132	1.43196725845337	266.075012207031	0.00314328004606068	281.493804931641